Workbook

Sheet Dashboard
A1: eBay PPC Product Pause Automation
A2: LEDSone · eBay UK · Promoted Listings ACOS / Stock governance
A3: Data window: uploaded eBay Promoted Listings export · 01–07 Jul 2026 (7-day) · snapshot
A5: Metric | B5: Value
A6: Listings in scope | B6: =COUNTA('Pause Log'!$B$3:$B$44) -> 42
A7: Listings paused | B7: =COUNTIF('Pause Log'!$H$3:$H$44,"PAUSED") -> 16
A8: — High priority | B8: =COUNTIF('Pause Log'!$F$3:$F$44,"High") -> 5
A9: — Medium priority | B9: =COUNTIF('Pause Log'!$F$3:$F$44,"Medium") -> 6
A10: — Low priority | B10: =COUNTIF('Pause Log'!$F$3:$F$44,"Low") -> 5
A11: Stock rule hits | B11: =COUNTIF('Pause Log'!$E$3:$E$44,"Stock") -> 8
A12: Rule 1 hits (high ACOS) | B12: =COUNTIF('Pause Log'!$E$3:$E$44,"Rule 1") -> 7
A13: Rule 2 hits (no sales + clicks) | B13: =COUNTIF('Pause Log'!$E$3:$E$44,"Rule 2") -> 1
A14: Still running | B14: =COUNTIF('Pause Log'!$H$3:$H$44,"RUNNING") -> 19
A15: Already off | B15: =COUNTIF('Pause Log'!$H$3:$H$44,"ALREADY OFF") -> 7
A16: 30D spend at risk (paused) | B16: =SUMIF('Pause Log'!$H$3:$H$44,"PAUSED",'Input Data'!$K$3:$K$44) -> 416.94
A17: 30D spend — all listings | B17: =SUM('Input Data'!$K$3:$K$44) -> 1243.09

Sheet Pause Log
A1: LISTING | D1: AUTO-PAUSE DECISION (computed) | I1: CPPC REVIEW (staff)
A2: Campaign / Listing | B2: Item ID / SKU | C2: Stock | D2: State | E2: Rule | F2: Priority | G2: Reason | H2: Status | I2: Decision | J2: Note
A3: JD | Target Mixed | New | ST | smart | B3: 164113429012 | C3: ='Input Data'!$D$3&" units · "&IF('Input Data'!$D$3<=0,"Out of stock",IF('Input Data'!$D$3<'Pause Rules'!$B$4,"Low stock","In stock")) -> 82 units · In stock | D3: ="Campaign "&'Input Data'!$M$3&" / Listing "&'Input Data'!$N$3 -> Campaign ON / Listing ON | E3: =IF($L3,"—",IF($M3,"Stock",IF($N3,"Rule 1",IF($O3,"Rule 2","—")))) -> Rule 1 | F3: =IF(NOT($P3),"—",IF(AND($E3="Stock",'Input Data'!$D$3<=0),"High",IF('Input Data'!$K$3>='Pause Rules'!$B$9,"High",IF('Input Data'!$K$3>='Pause Rules'!$B$10,"Medium","Low")))) -> High | G3: =IF($L3,IF('Input Data'!$M$3="OFF","Campaign","Listing")&" is already OFF — pause rules are not evaluated.",IF($M3,IF('Input Data'!$D$3<=0,"Out of stock (0 units) — ads paused so spend does not run on an unbuyable item.","Low stock ("&'Input Data'!$D$3&" units, below the "&'Pause Rules'!$B$4&"-unit floor) — ads paused to protect the remaining units."),IF($N3,"30D ACOS "&'Input Data'!$E$3&"% is at or above the "&'Pause Rules'!$B$5&"% ceiling; 7D ACOS "&'Input Data'!$F$3&"% is not improving — paused.",IF($O3,'Input Data'!$I$3&" clicks over 14 days with 0 orders; spend "&TEXT('Input Data'!$J$3,"£0.00")&" is at or above the "&TEXT('Pause Rules'!$B$8,"£0.00")&" floor — paused.","No rule matched — the listing keeps running.")))) -> 30D ACOS 46.7% is at or above the 40% ceiling; 7D ACOS 46.7% is not improving — paused. | H3: =IF($L3,"ALREADY OFF",IF($P3,"PAUSED","RUNNING")) -> PAUSED | I3: Pending | L3: =OR('Input Data'!$M$3="OFF",'Input Data'!$N$3="OFF") -> FALSE | M3: =AND('Pause Rules'!$B$11,'Input Data'!$D$3<'Pause Rules'!$B$4) -> FALSE | N3: =AND('Pause Rules'!$B$12,'Input Data'!$G$3>0,'Input Data'!$E$3>='Pause Rules'!$B$5,NOT('Input Data'!$F$3<'Pause Rules'!$B$6)) -> TRUE | O3: =AND('Pause Rules'!$B$13,'Input Data'!$H$3=0,'Input Data'!$I$3>='Pause Rules'!$B$7,NOT('Input Data'!$J$3<'Pause Rules'!$B$8)) -> FALSE | P3: =AND(NOT($L3),OR($M3,$N3,$O3)) -> TRUE
A4: JD | Without general | Manual | B4: 144201913012 | C4: ='Input Data'!$D$4&" units · "&IF('Input Data'!$D$4<=0,"Out of stock",IF('Input Data'!$D$4<'Pause Rules'!$B$4,"Low stock","In stock")) -> 73 units · In stock | D4: ="Campaign "&'Input Data'!$M$4&" / Listing "&'Input Data'!$N$4 -> Campaign ON / Listing ON | E4: =IF($L4,"—",IF($M4,"Stock",IF($N4,"Rule 1",IF($O4,"Rule 2","—")))) -> Rule 1 | F4: =IF(NOT($P4),"—",IF(AND($E4="Stock",'Input Data'!$D$4<=0),"High",IF('Input Data'!$K$4>='Pause Rules'!$B$9,"High",IF('Input Data'!$K$4>='Pause Rules'!$B$10,"Medium","Low")))) -> High | G4: =IF($L4,IF('Input Data'!$M$4="OFF","Campaign","Listing")&" is already OFF — pause rules are not evaluated.",IF($M4,IF('Input Data'!$D$4<=0,"Out of stock (0 units) — ads paused so spend does not run on an unbuyable item.","Low stock ("&'Input Data'!$D$4&" units, below the "&'Pause Rules'!$B$4&"-unit floor) — ads paused to protect the remaining units."),IF($N4,"30D ACOS "&'Input Data'!$E$4&"% is at or above the "&'Pause Rules'!$B$5&"% ceiling; 7D ACOS "&'Input Data'!$F$4&"% is not improving — paused.",IF($O4,'Input Data'!$I$4&" clicks over 14 days with 0 orders; spend "&TEXT('Input Data'!$J$4,"£0.00")&" is at or above the "&TEXT('Pause Rules'!$B$8,"£0.00")&" floor — paused.","No rule matched — the listing keeps running.")))) -> 30D ACOS 40.6% is at or above the 40% ceiling; 7D ACOS 40.6% is not improving — paused. | H4: =IF($L4,"ALREADY OFF",IF($P4,"PAUSED","RUNNING")) -> PAUSED | I4: Pending | L4: =OR('Input Data'!$M$4="OFF",'Input Data'!$N$4="OFF") -> FALSE | M4: =AND('Pause Rules'!$B$11,'Input Data'!$D$4<'Pause Rules'!$B$4) -> FALSE | N4: =AND('Pause Rules'!$B$12,'Input Data'!$G$4>0,'Input Data'!$E$4>='Pause Rules'!$B$5,NOT('Input Data'!$F$4<'Pause Rules'!$B$6)) -> TRUE | O4: =AND('Pause Rules'!$B$13,'Input Data'!$H$4=0,'Input Data'!$I$4>='Pause Rules'!$B$7,NOT('Input Data'!$J$4<'Pause Rules'!$B$8)) -> FALSE | P4: =AND(NOT($L4),OR($M4,$N4,$O4)) -> TRUE
A5: JD | PH | Lampshade | Utharsika | Manual | B5: 129690966012 | C5: ='Input Data'!$D$5&" units · "&IF('Input Data'!$D$5<=0,"Out of stock",IF('Input Data'!$D$5<'Pause Rules'!$B$4,"Low stock","In stock")) -> 156 units · In stock | D5: ="Campaign "&'Input Data'!$M$5&" / Listing "&'Input Data'!$N$5 -> Campaign ON / Listing ON | E5: =IF($L5,"—",IF($M5,"Stock",IF($N5,"Rule 1",IF($O5,"Rule 2","—")))) -> Rule 1 | F5: =IF(NOT($P5),"—",IF(AND($E5="Stock",'Input Data'!$D$5<=0),"High",IF('Input Data'!$K$5>='Pause Rules'!$B$9,"High",IF('Input Data'!$K$5>='Pause Rules'!$B$10,"Medium","Low")))) -> High | G5: =IF($L5,IF('Input Data'!$M$5="OFF","Campaign","Listing")&" is already OFF — pause rules are not evaluated.",IF($M5,IF('Input Data'!$D$5<=0,"Out of stock (0 units) — ads paused so spend does not run on an unbuyable item.","Low stock ("&'Input Data'!$D$5&" units, below the "&'Pause Rules'!$B$4&"-unit floor) — ads paused to protect the remaining units."),IF($N5,"30D ACOS "&'Input Data'!$E$5&"% is at or above the "&'Pause Rules'!$B$5&"% ceiling; 7D ACOS "&'Input Data'!$F$5&"% is not improving — paused.",IF($O5,'Input Data'!$I$5&" clicks over 14 days with 0 orders; spend "&TEXT('Input Data'!$J$5,"£0.00")&" is at or above the "&TEXT('Pause Rules'!$B$8,"£0.00")&" floor — paused.","No rule matched — the listing keeps running.")))) -> 30D ACOS 49% is at or above the 40% ceiling; 7D ACOS 49% is not improving — paused. | H5: =IF($L5,"ALREADY OFF",IF($P5,"PAUSED","RUNNING")) -> PAUSED | I5: Pending | L5: =OR('Input Data'!$M$5="OFF",'Input Data'!$N$5="OFF") -> FALSE | M5: =AND('Pause Rules'!$B$11,'Input Data'!$D$5<'Pause Rules'!$B$4) -> FALSE | N5: =AND('Pause Rules'!$B$12,'Input Data'!$G$5>0,'Input Data'!$E$5>='Pause Rules'!$B$5,NOT('Input Data'!$F$5<'Pause Rules'!$B$6)) -> TRUE | O5: =AND('Pause Rules'!$B$13,'Input Data'!$H$5=0,'Input Data'!$I$5>='Pause Rules'!$B$7,NOT('Input Data'!$J$5<'Pause Rules'!$B$8)) -> FALSE | P5: =AND(NOT($L5),OR($M5,$N5,$O5)) -> TRUE
A6: JD | Wall lights | New | Manual | B6: 164195009012 | C6: ='Input Data'!$D$6&" units · "&IF('Input Data'!$D$6<=0,"Out of stock",IF('Input Data'!$D$6<'Pause Rules'!$B$4,"Low stock","In stock")) -> 0 units · Out of stock | D6: ="Campaign "&'Input Data'!$M$6&" / Listing "&'Input Data'!$N$6 -> Campaign ON / Listing ON | E6: =IF($L6,"—",IF($M6,"Stock",IF($N6,"Rule 1",IF($O6,"Rule 2","—")))) -> Stock | F6: =IF(NOT($P6),"—",IF(AND($E6="Stock",'Input Data'!$D$6<=0),"High",IF('Input Data'!$K$6>='Pause Rules'!$B$9,"High",IF('Input Data'!$K$6>='Pause Rules'!$B$10,"Medium","Low")))) -> High | G6: =IF($L6,IF('Input Data'!$M$6="OFF","Campaign","Listing")&" is already OFF — pause rules are not evaluated.",IF($M6,IF('Input Data'!$D$6<=0,"Out of stock (0 units) — ads paused so spend does not run on an unbuyable item.","Low stock ("&'Input Data'!$D$6&" units, below the "&'Pause Rules'!$B$4&"-unit floor) — ads paused to protect the remaining units."),IF($N6,"30D ACOS "&'Input Data'!$E$6&"% is at or above the "&'Pause Rules'!$B$5&"% ceiling; 7D ACOS "&'Input Data'!$F$6&"% is not improving — paused.",IF($O6,'Input Data'!$I$6&" clicks over 14 days with 0 orders; spend "&TEXT('Input Data'!$J$6,"£0.00")&" is at or above the "&TEXT('Pause Rules'!$B$8,"£0.00")&" floor — paused.","No rule matched — the listing keeps running.")))) -> Out of stock (0 units) — ads paused so spend does not run on an unbuyable item. | H6: =IF($L6,"ALREADY OFF",IF($P6,"PAUSED","RUNNING")) -> PAUSED | I6: Pending | L6: =OR('Input Data'!$M$6="OFF",'Input Data'!$N$6="OFF") -> FALSE | M6: =AND('Pause Rules'!$B$11,'Input Data'!$D$6<'Pause Rules'!$B$4) -> TRUE | N6: =AND('Pause Rules'!$B$12,'Input Data'!$G$6>0,'Input Data'!$E$6>='Pause Rules'!$B$5,NOT('Input Data'!$F$6<'Pause Rules'!$B$6)) -> FALSE | O6: =AND('Pause Rules'!$B$13,'Input Data'!$H$6=0,'Input Data'!$I$6>='Pause Rules'!$B$7,NOT('Input Data'!$J$6<'Pause Rules'!$B$8)) -> FALSE | P6: =AND(NOT($L6),OR($M6,$N6,$O6)) -> TRUE
A7: JD | PH | Pendant Light Fitting | Tharshana | Manual | B7: 160677049012 | C7: ='Input Data'!$D$7&" units · "&IF('Input Data'!$D$7<=0,"Out of stock",IF('Input Data'!$D$7<'Pause Rules'!$B$4,"Low stock","In stock")) -> 0 units · Out of stock | D7: ="Campaign "&'Input Data'!$M$7&" / Listing "&'Input Data'!$N$7 -> Campaign ON / Listing ON | E7: =IF($L7,"—",IF($M7,"Stock",IF($N7,"Rule 1",IF($O7,"Rule 2","—")))) -> Stock | F7: =IF(NOT($P7),"—",IF(AND($E7="Stock",'Input Data'!$D$7<=0),"High",IF('Input Data'!$K$7>='Pause Rules'!$B$9,"High",IF('Input Data'!$K$7>='Pause Rules'!$B$10,"Medium","Low")))) -> High | G7: =IF($L7,IF('Input Data'!$M$7="OFF","Campaign","Listing")&" is already OFF — pause rules are not evaluated.",IF($M7,IF('Input Data'!$D$7<=0,"Out of stock (0 units) — ads paused so spend does not run on an unbuyable item.","Low stock ("&'Input Data'!$D$7&" units, below the "&'Pause Rules'!$B$4&"-unit floor) — ads paused to protect the remaining units."),IF($N7,"30D ACOS "&'Input Data'!$E$7&"% is at or above the "&'Pause Rules'!$B$5&"% ceiling; 7D ACOS "&'Input Data'!$F$7&"% is not improving — paused.",IF($O7,'Input Data'!$I$7&" clicks over 14 days with 0 orders; spend "&TEXT('Input Data'!$J$7,"£0.00")&" is at or above the "&TEXT('Pause Rules'!$B$8,"£0.00")&" floor — paused.","No rule matched — the listing keeps running.")))) -> Out of stock (0 units) — ads paused so spend does not run on an unbuyable item. | H7: =IF($L7,"ALREADY OFF",IF($P7,"PAUSED","RUNNING")) -> PAUSED | I7: Pending | L7: =OR('Input Data'!$M$7="OFF",'Input Data'!$N$7="OFF") -> FALSE | M7: =AND('Pause Rules'!$B$11,'Input Data'!$D$7<'Pause Rules'!$B$4) -> TRUE | N7: =AND('Pause Rules'!$B$12,'Input Data'!$G$7>0,'Input Data'!$E$7>='Pause Rules'!$B$5,NOT('Input Data'!$F$7<'Pause Rules'!$B$6)) -> FALSE | O7: =AND('Pause Rules'!$B$13,'Input Data'!$H$7=0,'Input Data'!$I$7>='Pause Rules'!$B$7,NOT('Input Data'!$J$7<'Pause Rules'!$B$8)) -> FALSE | P7: =AND(NOT($L7),OR($M7,$N7,$O7)) -> TRUE
A8: JD | PSU+Bulbs | Transformer | Manual | B8: 153333633012 | C8: ='Input Data'!$D$8&" units · "&IF('Input Data'!$D$8<=0,"Out of stock",IF('Input Data'!$D$8<'Pause Rules'!$B$4,"Low stock","In stock")) -> 4 units · Low stock | D8: ="Campaign "&'Input Data'!$M$8&" / Listing "&'Input Data'!$N$8 -> Campaign ON / Listing ON | E8: =IF($L8,"—",IF($M8,"Stock",IF($N8,"Rule 1",IF($O8,"Rule 2","—")))) -> Stock | F8: =IF(NOT($P8),"—",IF(AND($E8="Stock",'Input Data'!$D$8<=0),"High",IF('Input Data'!$K$8>='Pause Rules'!$B$9,"High",IF('Input Data'!$K$8>='Pause Rules'!$B$10,"Medium","Low")))) -> Medium | G8: =IF($L8,IF('Input Data'!$M$8="OFF","Campaign","Listing")&" is already OFF — pause rules are not evaluated.",IF($M8,IF('Input Data'!$D$8<=0,"Out of stock (0 units) — ads paused so spend does not run on an unbuyable item.","Low stock ("&'Input Data'!$D$8&" units, below the "&'Pause Rules'!$B$4&"-unit floor) — ads paused to protect the remaining units."),IF($N8,"30D ACOS "&'Input Data'!$E$8&"% is at or above the "&'Pause Rules'!$B$5&"% ceiling; 7D ACOS "&'Input Data'!$F$8&"% is not improving — paused.",IF($O8,'Input Data'!$I$8&" clicks over 14 days with 0 orders; spend "&TEXT('Input Data'!$J$8,"£0.00")&" is at or above the "&TEXT('Pause Rules'!$B$8,"£0.00")&" floor — paused.","No rule matched — the listing keeps running.")))) -> Low stock (4 units, below the 5-unit floor) — ads paused to protect the remaining units. | H8: =IF($L8,"ALREADY OFF",IF($P8,"PAUSED","RUNNING")) -> PAUSED | I8: Pending | L8: =OR('Input Data'!$M$8="OFF",'Input Data'!$N$8="OFF") -> FALSE | M8: =AND('Pause Rules'!$B$11,'Input Data'!$D$8<'Pause Rules'!$B$4) -> TRUE | N8: =AND('Pause Rules'!$B$12,'Input Data'!$G$8>0,'Input Data'!$E$8>='Pause Rules'!$B$5,NOT('Input Data'!$F$8<'Pause Rules'!$B$6)) -> FALSE | O8: =AND('Pause Rules'!$B$13,'Input Data'!$H$8=0,'Input Data'!$I$8>='Pause Rules'!$B$7,NOT('Input Data'!$J$8<'Pause Rules'!$B$8)) -> FALSE | P8: =AND(NOT($L8),OR($M8,$N8,$O8)) -> TRUE
A9: JD | stock clearance products | Smart | B9: 28863477012 | C9: ='Input Data'!$D$9&" units · "&IF('Input Data'!$D$9<=0,"Out of stock",IF('Input Data'!$D$9<'Pause Rules'!$B$4,"Low stock","In stock")) -> 6 units · In stock | D9: ="Campaign "&'Input Data'!$M$9&" / Listing "&'Input Data'!$N$9 -> Campaign ON / Listing ON | E9: =IF($L9,"—",IF($M9,"Stock",IF($N9,"Rule 1",IF($O9,"Rule 2","—")))) -> Rule 1 | F9: =IF(NOT($P9),"—",IF(AND($E9="Stock",'Input Data'!$D$9<=0),"High",IF('Input Data'!$K$9>='Pause Rules'!$B$9,"High",IF('Input Data'!$K$9>='Pause Rules'!$B$10,"Medium","Low")))) -> Medium | G9: =IF($L9,IF('Input Data'!$M$9="OFF","Campaign","Listing")&" is already OFF — pause rules are not evaluated.",IF($M9,IF('Input Data'!$D$9<=0,"Out of stock (0 units) — ads paused so spend does not run on an unbuyable item.","Low stock ("&'Input Data'!$D$9&" units, below the "&'Pause Rules'!$B$4&"-unit floor) — ads paused to protect the remaining units."),IF($N9,"30D ACOS "&'Input Data'!$E$9&"% is at or above the "&'Pause Rules'!$B$5&"% ceiling; 7D ACOS "&'Input Data'!$F$9&"% is not improving — paused.",IF($O9,'Input Data'!$I$9&" clicks over 14 days with 0 orders; spend "&TEXT('Input Data'!$J$9,"£0.00")&" is at or above the "&TEXT('Pause Rules'!$B$8,"£0.00")&" floor — paused.","No rule matched — the listing keeps running.")))) -> 30D ACOS 47.7% is at or above the 40% ceiling; 7D ACOS 47.7% is not improving — paused. | H9: =IF($L9,"ALREADY OFF",IF($P9,"PAUSED","RUNNING")) -> PAUSED | I9: Pending | L9: =OR('Input Data'!$M$9="OFF",'Input Data'!$N$9="OFF") -> FALSE | M9: =AND('Pause Rules'!$B$11,'Input Data'!$D$9<'Pause Rules'!$B$4) -> FALSE | N9: =AND('Pause Rules'!$B$12,'Input Data'!$G$9>0,'Input Data'!$E$9>='Pause Rules'!$B$5,NOT('Input Data'!$F$9<'Pause Rules'!$B$6)) -> TRUE | O9: =AND('Pause Rules'!$B$13,'Input Data'!$H$9=0,'Input Data'!$I$9>='Pause Rules'!$B$7,NOT('Input Data'!$J$9<'Pause Rules'!$B$8)) -> FALSE | P9: =AND(NOT($L9),OR($M9,$N9,$O9)) -> TRUE
A10: JD | MH | 3 head Pendent | Smart | B10: 135730419012 | C10: ='Input Data'!$D$10&" units · "&IF('Input Data'!$D$10<=0,"Out of stock",IF('Input Data'!$D$10<'Pause Rules'!$B$4,"Low stock","In stock")) -> 31 units · In stock | D10: ="Campaign "&'Input Data'!$M$10&" / Listing "&'Input Data'!$N$10 -> Campaign ON / Listing ON | E10: =IF($L10,"—",IF($M10,"Stock",IF($N10,"Rule 1",IF($O10,"Rule 2","—")))) -> Rule 1 | F10: =IF(NOT($P10),"—",IF(AND($E10="Stock",'Input Data'!$D$10<=0),"High",IF('Input Data'!$K$10>='Pause Rules'!$B$9,"High",IF('Input Data'!$K$10>='Pause Rules'!$B$10,"Medium","Low")))) -> Medium | G10: =IF($L10,IF('Input Data'!$M$10="OFF","Campaign","Listing")&" is already OFF — pause rules are not evaluated.",IF($M10,IF('Input Data'!$D$10<=0,"Out of stock (0 units) — ads paused so spend does not run on an unbuyable item.","Low stock ("&'Input Data'!$D$10&" units, below the "&'Pause Rules'!$B$4&"-unit floor) — ads paused to protect the remaining units."),IF($N10,"30D ACOS "&'Input Data'!$E$10&"% is at or above the "&'Pause Rules'!$B$5&"% ceiling; 7D ACOS "&'Input Data'!$F$10&"% is not improving — paused.",IF($O10,'Input Data'!$I$10&" clicks over 14 days with 0 orders; spend "&TEXT('Input Data'!$J$10,"£0.00")&" is at or above the "&TEXT('Pause Rules'!$B$8,"£0.00")&" floor — paused.","No rule matched — the listing keeps running.")))) -> 30D ACOS 86.1% is at or above the 40% ceiling; 7D ACOS 86.1% is not improving — paused. | H10: =IF($L10,"ALREADY OFF",IF($P10,"PAUSED","RUNNING")) -> PAUSED | I10: Pending | L10: =OR('Input Data'!$M$10="OFF",'Input Data'!$N$10="OFF") -> FALSE | M10: =AND('Pause Rules'!$B$11,'Input Data'!$D$10<'Pause Rules'!$B$4) -> FALSE | N10: =AND('Pause Rules'!$B$12,'Input Data'!$G$10>0,'Input Data'!$E$10>='Pause Rules'!$B$5,NOT('Input Data'!$F$10<'Pause Rules'!$B$6)) -> TRUE | O10: =AND('Pause Rules'!$B$13,'Input Data'!$H$10=0,'Input Data'!$I$10>='Pause Rules'!$B$7,NOT('Input Data'!$J$10<'Pause Rules'!$B$8)) -> FALSE | P10: =AND(NOT($L10),OR($M10,$N10,$O10)) -> TRUE
A11: JD | Shade+video campaign | B11: 163710397012 | C11: ='Input Data'!$D$11&" units · "&IF('Input Data'!$D$11<=0,"Out of stock",IF('Input Data'!$D$11<'Pause Rules'!$B$4,"Low stock","In stock")) -> 88 units · In stock | D11: ="Campaign "&'Input Data'!$M$11&" / Listing "&'Input Data'!$N$11 -> Campaign ON / Listing ON | E11: =IF($L11,"—",IF($M11,"Stock",IF($N11,"Rule 1",IF($O11,"Rule 2","—")))) -> Rule 1 | F11: =IF(NOT($P11),"—",IF(AND($E11="Stock",'Input Data'!$D$11<=0),"High",IF('Input Data'!$K$11>='Pause Rules'!$B$9,"High",IF('Input Data'!$K$11>='Pause Rules'!$B$10,"Medium","Low")))) -> Medium | G11: =IF($L11,IF('Input Data'!$M$11="OFF","Campaign","Listing")&" is already OFF — pause rules are not evaluated.",IF($M11,IF('Input Data'!$D$11<=0,"Out of stock (0 units) — ads paused so spend does not run on an unbuyable item.","Low stock ("&'Input Data'!$D$11&" units, below the "&'Pause Rules'!$B$4&"-unit floor) — ads paused to protect the remaining units."),IF($N11,"30D ACOS "&'Input Data'!$E$11&"% is at or above the "&'Pause Rules'!$B$5&"% ceiling; 7D ACOS "&'Input Data'!$F$11&"% is not improving — paused.",IF($O11,'Input Data'!$I$11&" clicks over 14 days with 0 orders; spend "&TEXT('Input Data'!$J$11,"£0.00")&" is at or above the "&TEXT('Pause Rules'!$B$8,"£0.00")&" floor — paused.","No rule matched — the listing keeps running.")))) -> 30D ACOS 83.5% is at or above the 40% ceiling; 7D ACOS 83.5% is not improving — paused. | H11: =IF($L11,"ALREADY OFF",IF($P11,"PAUSED","RUNNING")) -> PAUSED | I11: Pending | L11: =OR('Input Data'!$M$11="OFF",'Input Data'!$N$11="OFF") -> FALSE | M11: =AND('Pause Rules'!$B$11,'Input Data'!$D$11<'Pause Rules'!$B$4) -> FALSE | N11: =AND('Pause Rules'!$B$12,'Input Data'!$G$11>0,'Input Data'!$E$11>='Pause Rules'!$B$5,NOT('Input Data'!$F$11<'Pause Rules'!$B$6)) -> TRUE | O11: =AND('Pause Rules'!$B$13,'Input Data'!$H$11=0,'Input Data'!$I$11>='Pause Rules'!$B$7,NOT('Input Data'!$J$11<'Pause Rules'!$B$8)) -> FALSE | P11: =AND(NOT($L11),OR($M11,$N11,$O11)) -> TRUE
A12: JD | Ceiling Lights | Manual | B12: 163193938012 | C12: ='Input Data'!$D$12&" units · "&IF('Input Data'!$D$12<=0,"Out of stock",IF('Input Data'!$D$12<'Pause Rules'!$B$4,"Low stock","In stock")) -> 44 units · In stock | D12: ="Campaign "&'Input Data'!$M$12&" / Listing "&'Input Data'!$N$12 -> Campaign ON / Listing ON | E12: =IF($L12,"—",IF($M12,"Stock",IF($N12,"Rule 1",IF($O12,"Rule 2","—")))) -> Rule 1 | F12: =IF(NOT($P12),"—",IF(AND($E12="Stock",'Input Data'!$D$12<=0),"High",IF('Input Data'!$K$12>='Pause Rules'!$B$9,"High",IF('Input Data'!$K$12>='Pause Rules'!$B$10,"Medium","Low")))) -> Medium | G12: =IF($L12,IF('Input Data'!$M$12="OFF","Campaign","Listing")&" is already OFF — pause rules are not evaluated.",IF($M12,IF('Input Data'!$D$12<=0,"Out of stock (0 units) — ads paused so spend does not run on an unbuyable item.","Low stock ("&'Input Data'!$D$12&" units, below the "&'Pause Rules'!$B$4&"-unit floor) — ads paused to protect the remaining units."),IF($N12,"30D ACOS "&'Input Data'!$E$12&"% is at or above the "&'Pause Rules'!$B$5&"% ceiling; 7D ACOS "&'Input Data'!$F$12&"% is not improving — paused.",IF($O12,'Input Data'!$I$12&" clicks over 14 days with 0 orders; spend "&TEXT('Input Data'!$J$12,"£0.00")&" is at or above the "&TEXT('Pause Rules'!$B$8,"£0.00")&" floor — paused.","No rule matched — the listing keeps running.")))) -> 30D ACOS 51.4% is at or above the 40% ceiling; 7D ACOS 51.4% is not improving — paused. | H12: =IF($L12,"ALREADY OFF",IF($P12,"PAUSED","RUNNING")) -> PAUSED | I12: Pending | L12: =OR('Input Data'!$M$12="OFF",'Input Data'!$N$12="OFF") -> FALSE | M12: =AND('Pause Rules'!$B$11,'Input Data'!$D$12<'Pause Rules'!$B$4) -> FALSE | N12: =AND('Pause Rules'!$B$12,'Input Data'!$G$12>0,'Input Data'!$E$12>='Pause Rules'!$B$5,NOT('Input Data'!$F$12<'Pause Rules'!$B$6)) -> TRUE | O12: =AND('Pause Rules'!$B$13,'Input Data'!$H$12=0,'Input Data'!$I$12>='Pause Rules'!$B$7,NOT('Input Data'!$J$12<'Pause Rules'!$B$8)) -> FALSE | P12: =AND(NOT($L12),OR($M12,$N12,$O12)) -> TRUE
A13: JD | Plug in light | Manual | B13: 164267739012 | C13: ='Input Data'!$D$13&" units · "&IF('Input Data'!$D$13<=0,"Out of stock",IF('Input Data'!$D$13<'Pause Rules'!$B$4,"Low stock","In stock")) -> 3 units · Low stock | D13: ="Campaign "&'Input Data'!$M$13&" / Listing "&'Input Data'!$N$13 -> Campaign ON / Listing ON | E13: =IF($L13,"—",IF($M13,"Stock",IF($N13,"Rule 1",IF($O13,"Rule 2","—")))) -> Stock | F13: =IF(NOT($P13),"—",IF(AND($E13="Stock",'Input Data'!$D$13<=0),"High",IF('Input Data'!$K$13>='Pause Rules'!$B$9,"High",IF('Input Data'!$K$13>='Pause Rules'!$B$10,"Medium","Low")))) -> Medium | G13: =IF($L13,IF('Input Data'!$M$13="OFF","Campaign","Listing")&" is already OFF — pause rules are not evaluated.",IF($M13,IF('Input Data'!$D$13<=0,"Out of stock (0 units) — ads paused so spend does not run on an unbuyable item.","Low stock ("&'Input Data'!$D$13&" units, below the "&'Pause Rules'!$B$4&"-unit floor) — ads paused to protect the remaining units."),IF($N13,"30D ACOS "&'Input Data'!$E$13&"% is at or above the "&'Pause Rules'!$B$5&"% ceiling; 7D ACOS "&'Input Data'!$F$13&"% is not improving — paused.",IF($O13,'Input Data'!$I$13&" clicks over 14 days with 0 orders; spend "&TEXT('Input Data'!$J$13,"£0.00")&" is at or above the "&TEXT('Pause Rules'!$B$8,"£0.00")&" floor — paused.","No rule matched — the listing keeps running.")))) -> Low stock (3 units, below the 5-unit floor) — ads paused to protect the remaining units. | H13: =IF($L13,"ALREADY OFF",IF($P13,"PAUSED","RUNNING")) -> PAUSED | I13: Pending | L13: =OR('Input Data'!$M$13="OFF",'Input Data'!$N$13="OFF") -> FALSE | M13: =AND('Pause Rules'!$B$11,'Input Data'!$D$13<'Pause Rules'!$B$4) -> TRUE | N13: =AND('Pause Rules'!$B$12,'Input Data'!$G$13>0,'Input Data'!$E$13>='Pause Rules'!$B$5,NOT('Input Data'!$F$13<'Pause Rules'!$B$6)) -> FALSE | O13: =AND('Pause Rules'!$B$13,'Input Data'!$H$13=0,'Input Data'!$I$13>='Pause Rules'!$B$7,NOT('Input Data'!$J$13<'Pause Rules'!$B$8)) -> FALSE | P13: =AND(NOT($L13),OR($M13,$N13,$O13)) -> TRUE
A14: JD | PH | 3 head pendant light | Manual | B14: 164421244012 | C14: ='Input Data'!$D$14&" units · "&IF('Input Data'!$D$14<=0,"Out of stock",IF('Input Data'!$D$14<'Pause Rules'!$B$4,"Low stock","In stock")) -> 2 units · Low stock | D14: ="Campaign "&'Input Data'!$M$14&" / Listing "&'Input Data'!$N$14 -> Campaign ON / Listing ON | E14: =IF($L14,"—",IF($M14,"Stock",IF($N14,"Rule 1",IF($O14,"Rule 2","—")))) -> Stock | F14: =IF(NOT($P14),"—",IF(AND($E14="Stock",'Input Data'!$D$14<=0),"High",IF('Input Data'!$K$14>='Pause Rules'!$B$9,"High",IF('Input Data'!$K$14>='Pause Rules'!$B$10,"Medium","Low")))) -> Low | G14: =IF($L14,IF('Input Data'!$M$14="OFF","Campaign","Listing")&" is already OFF — pause rules are not evaluated.",IF($M14,IF('Input Data'!$D$14<=0,"Out of stock (0 units) — ads paused so spend does not run on an unbuyable item.","Low stock ("&'Input Data'!$D$14&" units, below the "&'Pause Rules'!$B$4&"-unit floor) — ads paused to protect the remaining units."),IF($N14,"30D ACOS "&'Input Data'!$E$14&"% is at or above the "&'Pause Rules'!$B$5&"% ceiling; 7D ACOS "&'Input Data'!$F$14&"% is not improving — paused.",IF($O14,'Input Data'!$I$14&" clicks over 14 days with 0 orders; spend "&TEXT('Input Data'!$J$14,"£0.00")&" is at or above the "&TEXT('Pause Rules'!$B$8,"£0.00")&" floor — paused.","No rule matched — the listing keeps running.")))) -> Low stock (2 units, below the 5-unit floor) — ads paused to protect the remaining units. | H14: =IF($L14,"ALREADY OFF",IF($P14,"PAUSED","RUNNING")) -> PAUSED | I14: Pending | L14: =OR('Input Data'!$M$14="OFF",'Input Data'!$N$14="OFF") -> FALSE | M14: =AND('Pause Rules'!$B$11,'Input Data'!$D$14<'Pause Rules'!$B$4) -> TRUE | N14: =AND('Pause Rules'!$B$12,'Input Data'!$G$14>0,'Input Data'!$E$14>='Pause Rules'!$B$5,NOT('Input Data'!$F$14<'Pause Rules'!$B$6)) -> FALSE | O14: =AND('Pause Rules'!$B$13,'Input Data'!$H$14=0,'Input Data'!$I$14>='Pause Rules'!$B$7,NOT('Input Data'!$J$14<'Pause Rules'!$B$8)) -> FALSE | P14: =AND(NOT($L14),OR($M14,$N14,$O14)) -> TRUE
A15: JD | PH | Flush light | Manual | B15: 26896653012 | C15: ='Input Data'!$D$15&" units · "&IF('Input Data'!$D$15<=0,"Out of stock",IF('Input Data'!$D$15<'Pause Rules'!$B$4,"Low stock","In stock")) -> 1 units · Low stock | D15: ="Campaign "&'Input Data'!$M$15&" / Listing "&'Input Data'!$N$15 -> Campaign ON / Listing ON | E15: =IF($L15,"—",IF($M15,"Stock",IF($N15,"Rule 1",IF($O15,"Rule 2","—")))) -> Stock | F15: =IF(NOT($P15),"—",IF(AND($E15="Stock",'Input Data'!$D$15<=0),"High",IF('Input Data'!$K$15>='Pause Rules'!$B$9,"High",IF('Input Data'!$K$15>='Pause Rules'!$B$10,"Medium","Low")))) -> Low | G15: =IF($L15,IF('Input Data'!$M$15="OFF","Campaign","Listing")&" is already OFF — pause rules are not evaluated.",IF($M15,IF('Input Data'!$D$15<=0,"Out of stock (0 units) — ads paused so spend does not run on an unbuyable item.","Low stock ("&'Input Data'!$D$15&" units, below the "&'Pause Rules'!$B$4&"-unit floor) — ads paused to protect the remaining units."),IF($N15,"30D ACOS "&'Input Data'!$E$15&"% is at or above the "&'Pause Rules'!$B$5&"% ceiling; 7D ACOS "&'Input Data'!$F$15&"% is not improving — paused.",IF($O15,'Input Data'!$I$15&" clicks over 14 days with 0 orders; spend "&TEXT('Input Data'!$J$15,"£0.00")&" is at or above the "&TEXT('Pause Rules'!$B$8,"£0.00")&" floor — paused.","No rule matched — the listing keeps running.")))) -> Low stock (1 units, below the 5-unit floor) — ads paused to protect the remaining units. | H15: =IF($L15,"ALREADY OFF",IF($P15,"PAUSED","RUNNING")) -> PAUSED | I15: Pending | L15: =OR('Input Data'!$M$15="OFF",'Input Data'!$N$15="OFF") -> FALSE | M15: =AND('Pause Rules'!$B$11,'Input Data'!$D$15<'Pause Rules'!$B$4) -> TRUE | N15: =AND('Pause Rules'!$B$12,'Input Data'!$G$15>0,'Input Data'!$E$15>='Pause Rules'!$B$5,NOT('Input Data'!$F$15<'Pause Rules'!$B$6)) -> FALSE | O15: =AND('Pause Rules'!$B$13,'Input Data'!$H$15=0,'Input Data'!$I$15>='Pause Rules'!$B$7,NOT('Input Data'!$J$15<'Pause Rules'!$B$8)) -> FALSE | P15: =AND(NOT($L15),OR($M15,$N15,$O15)) -> TRUE
A16: JD | MH | Flush Light & Lamp Shade | Shanthini | Manual | B16: 159902435012 | C16: ='Input Data'!$D$16&" units · "&IF('Input Data'!$D$16<=0,"Out of stock",IF('Input Data'!$D$16<'Pause Rules'!$B$4,"Low stock","In stock")) -> 2 units · Low stock | D16: ="Campaign "&'Input Data'!$M$16&" / Listing "&'Input Data'!$N$16 -> Campaign ON / Listing ON | E16: =IF($L16,"—",IF($M16,"Stock",IF($N16,"Rule 1",IF($O16,"Rule 2","—")))) -> Stock | F16: =IF(NOT($P16),"—",IF(AND($E16="Stock",'Input Data'!$D$16<=0),"High",IF('Input Data'!$K$16>='Pause Rules'!$B$9,"High",IF('Input Data'!$K$16>='Pause Rules'!$B$10,"Medium","Low")))) -> Low | G16: =IF($L16,IF('Input Data'!$M$16="OFF","Campaign","Listing")&" is already OFF — pause rules are not evaluated.",IF($M16,IF('Input Data'!$D$16<=0,"Out of stock (0 units) — ads paused so spend does not run on an unbuyable item.","Low stock ("&'Input Data'!$D$16&" units, below the "&'Pause Rules'!$B$4&"-unit floor) — ads paused to protect the remaining units."),IF($N16,"30D ACOS "&'Input Data'!$E$16&"% is at or above the "&'Pause Rules'!$B$5&"% ceiling; 7D ACOS "&'Input Data'!$F$16&"% is not improving — paused.",IF($O16,'Input Data'!$I$16&" clicks over 14 days with 0 orders; spend "&TEXT('Input Data'!$J$16,"£0.00")&" is at or above the "&TEXT('Pause Rules'!$B$8,"£0.00")&" floor — paused.","No rule matched — the listing keeps running.")))) -> Low stock (2 units, below the 5-unit floor) — ads paused to protect the remaining units. | H16: =IF($L16,"ALREADY OFF",IF($P16,"PAUSED","RUNNING")) -> PAUSED | I16: Pending | L16: =OR('Input Data'!$M$16="OFF",'Input Data'!$N$16="OFF") -> FALSE | M16: =AND('Pause Rules'!$B$11,'Input Data'!$D$16<'Pause Rules'!$B$4) -> TRUE | N16: =AND('Pause Rules'!$B$12,'Input Data'!$G$16>0,'Input Data'!$E$16>='Pause Rules'!$B$5,NOT('Input Data'!$F$16<'Pause Rules'!$B$6)) -> FALSE | O16: =AND('Pause Rules'!$B$13,'Input Data'!$H$16=0,'Input Data'!$I$16>='Pause Rules'!$B$7,NOT('Input Data'!$J$16<'Pause Rules'!$B$8)) -> FALSE | P16: =AND(NOT($L16),OR($M16,$N16,$O16)) -> TRUE
A17: JD | MH | Wall lights | Shimee | Manual | B17: 38338866012 | C17: ='Input Data'!$D$17&" units · "&IF('Input Data'!$D$17<=0,"Out of stock",IF('Input Data'!$D$17<'Pause Rules'!$B$4,"Low stock","In stock")) -> 47 units · In stock | D17: ="Campaign "&'Input Data'!$M$17&" / Listing "&'Input Data'!$N$17 -> Campaign ON / Listing ON | E17: =IF($L17,"—",IF($M17,"Stock",IF($N17,"Rule 1",IF($O17,"Rule 2","—")))) -> Rule 2 | F17: =IF(NOT($P17),"—",IF(AND($E17="Stock",'Input Data'!$D$17<=0),"High",IF('Input Data'!$K$17>='Pause Rules'!$B$9,"High",IF('Input Data'!$K$17>='Pause Rules'!$B$10,"Medium","Low")))) -> Low | G17: =IF($L17,IF('Input Data'!$M$17="OFF","Campaign","Listing")&" is already OFF — pause rules are not evaluated.",IF($M17,IF('Input Data'!$D$17<=0,"Out of stock (0 units) — ads paused so spend does not run on an unbuyable item.","Low stock ("&'Input Data'!$D$17&" units, below the "&'Pause Rules'!$B$4&"-unit floor) — ads paused to protect the remaining units."),IF($N17,"30D ACOS "&'Input Data'!$E$17&"% is at or above the "&'Pause Rules'!$B$5&"% ceiling; 7D ACOS "&'Input Data'!$F$17&"% is not improving — paused.",IF($O17,'Input Data'!$I$17&" clicks over 14 days with 0 orders; spend "&TEXT('Input Data'!$J$17,"£0.00")&" is at or above the "&TEXT('Pause Rules'!$B$8,"£0.00")&" floor — paused.","No rule matched — the listing keeps running.")))) -> 57 clicks over 14 days with 0 orders; spend £10.45 is at or above the £2.50 floor — paused. | H17: =IF($L17,"ALREADY OFF",IF($P17,"PAUSED","RUNNING")) -> PAUSED | I17: Pending | L17: =OR('Input Data'!$M$17="OFF",'Input Data'!$N$17="OFF") -> FALSE | M17: =AND('Pause Rules'!$B$11,'Input Data'!$D$17<'Pause Rules'!$B$4) -> FALSE | N17: =AND('Pause Rules'!$B$12,'Input Data'!$G$17>0,'Input Data'!$E$17>='Pause Rules'!$B$5,NOT('Input Data'!$F$17<'Pause Rules'!$B$6)) -> FALSE | O17: =AND('Pause Rules'!$B$13,'Input Data'!$H$17=0,'Input Data'!$I$17>='Pause Rules'!$B$7,NOT('Input Data'!$J$17<'Pause Rules'!$B$8)) -> TRUE | P17: =AND(NOT($L17),OR($M17,$N17,$O17)) -> TRUE
A18: JD | Cables | Video | Manual | B18: 165065723012 | C18: ='Input Data'!$D$18&" units · "&IF('Input Data'!$D$18<=0,"Out of stock",IF('Input Data'!$D$18<'Pause Rules'!$B$4,"Low stock","In stock")) -> 3 units · Low stock | D18: ="Campaign "&'Input Data'!$M$18&" / Listing "&'Input Data'!$N$18 -> Campaign ON / Listing ON | E18: =IF($L18,"—",IF($M18,"Stock",IF($N18,"Rule 1",IF($O18,"Rule 2","—")))) -> Stock | F18: =IF(NOT($P18),"—",IF(AND($E18="Stock",'Input Data'!$D$18<=0),"High",IF('Input Data'!$K$18>='Pause Rules'!$B$9,"High",IF('Input Data'!$K$18>='Pause Rules'!$B$10,"Medium","Low")))) -> Low | G18: =IF($L18,IF('Input Data'!$M$18="OFF","Campaign","Listing")&" is already OFF — pause rules are not evaluated.",IF($M18,IF('Input Data'!$D$18<=0,"Out of stock (0 units) — ads paused so spend does not run on an unbuyable item.","Low stock ("&'Input Data'!$D$18&" units, below the "&'Pause Rules'!$B$4&"-unit floor) — ads paused to protect the remaining units."),IF($N18,"30D ACOS "&'Input Data'!$E$18&"% is at or above the "&'Pause Rules'!$B$5&"% ceiling; 7D ACOS "&'Input Data'!$F$18&"% is not improving — paused.",IF($O18,'Input Data'!$I$18&" clicks over 14 days with 0 orders; spend "&TEXT('Input Data'!$J$18,"£0.00")&" is at or above the "&TEXT('Pause Rules'!$B$8,"£0.00")&" floor — paused.","No rule matched — the listing keeps running.")))) -> Low stock (3 units, below the 5-unit floor) — ads paused to protect the remaining units. | H18: =IF($L18,"ALREADY OFF",IF($P18,"PAUSED","RUNNING")) -> PAUSED | I18: Pending | L18: =OR('Input Data'!$M$18="OFF",'Input Data'!$N$18="OFF") -> FALSE | M18: =AND('Pause Rules'!$B$11,'Input Data'!$D$18<'Pause Rules'!$B$4) -> TRUE | N18: =AND('Pause Rules'!$B$12,'Input Data'!$G$18>0,'Input Data'!$E$18>='Pause Rules'!$B$5,NOT('Input Data'!$F$18<'Pause Rules'!$B$6)) -> FALSE | O18: =AND('Pause Rules'!$B$13,'Input Data'!$H$18=0,'Input Data'!$I$18>='Pause Rules'!$B$7,NOT('Input Data'!$J$18<'Pause Rules'!$B$8)) -> FALSE | P18: =AND(NOT($L18),OR($M18,$N18,$O18)) -> TRUE
A19: JD | PH | Tharsika | Lamp Holders | Manual | B19: 14841895012 | C19: ='Input Data'!$D$19&" units · "&IF('Input Data'!$D$19<=0,"Out of stock",IF('Input Data'!$D$19<'Pause Rules'!$B$4,"Low stock","In stock")) -> 55 units · In stock | D19: ="Campaign "&'Input Data'!$M$19&" / Listing "&'Input Data'!$N$19 -> Campaign OFF / Listing OFF | E19: =IF($L19,"—",IF($M19,"Stock",IF($N19,"Rule 1",IF($O19,"Rule 2","—")))) -> — | F19: =IF(NOT($P19),"—",IF(AND($E19="Stock",'Input Data'!$D$19<=0),"High",IF('Input Data'!$K$19>='Pause Rules'!$B$9,"High",IF('Input Data'!$K$19>='Pause Rules'!$B$10,"Medium","Low")))) -> — | G19: =IF($L19,IF('Input Data'!$M$19="OFF","Campaign","Listing")&" is already OFF — pause rules are not evaluated.",IF($M19,IF('Input Data'!$D$19<=0,"Out of stock (0 units) — ads paused so spend does not run on an unbuyable item.","Low stock ("&'Input Data'!$D$19&" units, below the "&'Pause Rules'!$B$4&"-unit floor) — ads paused to protect the remaining units."),IF($N19,"30D ACOS "&'Input Data'!$E$19&"% is at or above the "&'Pause Rules'!$B$5&"% ceiling; 7D ACOS "&'Input Data'!$F$19&"% is not improving — paused.",IF($O19,'Input Data'!$I$19&" clicks over 14 days with 0 orders; spend "&TEXT('Input Data'!$J$19,"£0.00")&" is at or above the "&TEXT('Pause Rules'!$B$8,"£0.00")&" floor — paused.","No rule matched — the listing keeps running.")))) -> Campaign is already OFF — pause rules are not evaluated. | H19: =IF($L19,"ALREADY OFF",IF($P19,"PAUSED","RUNNING")) -> ALREADY OFF | I19: Pending | L19: =OR('Input Data'!$M$19="OFF",'Input Data'!$N$19="OFF") -> TRUE | M19: =AND('Pause Rules'!$B$11,'Input Data'!$D$19<'Pause Rules'!$B$4) -> FALSE | N19: =AND('Pause Rules'!$B$12,'Input Data'!$G$19>0,'Input Data'!$E$19>='Pause Rules'!$B$5,NOT('Input Data'!$F$19<'Pause Rules'!$B$6)) -> TRUE | O19: =AND('Pause Rules'!$B$13,'Input Data'!$H$19=0,'Input Data'!$I$19>='Pause Rules'!$B$7,NOT('Input Data'!$J$19<'Pause Rules'!$B$8)) -> FALSE | P19: =AND(NOT($L19),OR($M19,$N19,$O19)) -> FALSE
A20: JD | Promotion Dec 2025 | smart | B20: 156649526012 | C20: ='Input Data'!$D$20&" units · "&IF('Input Data'!$D$20<=0,"Out of stock",IF('Input Data'!$D$20<'Pause Rules'!$B$4,"Low stock","In stock")) -> 9 units · In stock | D20: ="Campaign "&'Input Data'!$M$20&" / Listing "&'Input Data'!$N$20 -> Campaign OFF / Listing OFF | E20: =IF($L20,"—",IF($M20,"Stock",IF($N20,"Rule 1",IF($O20,"Rule 2","—")))) -> — | F20: =IF(NOT($P20),"—",IF(AND($E20="Stock",'Input Data'!$D$20<=0),"High",IF('Input Data'!$K$20>='Pause Rules'!$B$9,"High",IF('Input Data'!$K$20>='Pause Rules'!$B$10,"Medium","Low")))) -> — | G20: =IF($L20,IF('Input Data'!$M$20="OFF","Campaign","Listing")&" is already OFF — pause rules are not evaluated.",IF($M20,IF('Input Data'!$D$20<=0,"Out of stock (0 units) — ads paused so spend does not run on an unbuyable item.","Low stock ("&'Input Data'!$D$20&" units, below the "&'Pause Rules'!$B$4&"-unit floor) — ads paused to protect the remaining units."),IF($N20,"30D ACOS "&'Input Data'!$E$20&"% is at or above the "&'Pause Rules'!$B$5&"% ceiling; 7D ACOS "&'Input Data'!$F$20&"% is not improving — paused.",IF($O20,'Input Data'!$I$20&" clicks over 14 days with 0 orders; spend "&TEXT('Input Data'!$J$20,"£0.00")&" is at or above the "&TEXT('Pause Rules'!$B$8,"£0.00")&" floor — paused.","No rule matched — the listing keeps running.")))) -> Campaign is already OFF — pause rules are not evaluated. | H20: =IF($L20,"ALREADY OFF",IF($P20,"PAUSED","RUNNING")) -> ALREADY OFF | I20: Pending | L20: =OR('Input Data'!$M$20="OFF",'Input Data'!$N$20="OFF") -> TRUE | M20: =AND('Pause Rules'!$B$11,'Input Data'!$D$20<'Pause Rules'!$B$4) -> FALSE | N20: =AND('Pause Rules'!$B$12,'Input Data'!$G$20>0,'Input Data'!$E$20>='Pause Rules'!$B$5,NOT('Input Data'!$F$20<'Pause Rules'!$B$6)) -> FALSE | O20: =AND('Pause Rules'!$B$13,'Input Data'!$H$20=0,'Input Data'!$I$20>='Pause Rules'!$B$7,NOT('Input Data'!$J$20<'Pause Rules'!$B$8)) -> FALSE | P20: =AND(NOT($L20),OR($M20,$N20,$O20)) -> FALSE
A21: JD | Mixed Product | Manual | B21: 85734687012 | C21: ='Input Data'!$D$21&" units · "&IF('Input Data'!$D$21<=0,"Out of stock",IF('Input Data'!$D$21<'Pause Rules'!$B$4,"Low stock","In stock")) -> 12 units · In stock | D21: ="Campaign "&'Input Data'!$M$21&" / Listing "&'Input Data'!$N$21 -> Campaign OFF / Listing OFF | E21: =IF($L21,"—",IF($M21,"Stock",IF($N21,"Rule 1",IF($O21,"Rule 2","—")))) -> — | F21: =IF(NOT($P21),"—",IF(AND($E21="Stock",'Input Data'!$D$21<=0),"High",IF('Input Data'!$K$21>='Pause Rules'!$B$9,"High",IF('Input Data'!$K$21>='Pause Rules'!$B$10,"Medium","Low")))) -> — | G21: =IF($L21,IF('Input Data'!$M$21="OFF","Campaign","Listing")&" is already OFF — pause rules are not evaluated.",IF($M21,IF('Input Data'!$D$21<=0,"Out of stock (0 units) — ads paused so spend does not run on an unbuyable item.","Low stock ("&'Input Data'!$D$21&" units, below the "&'Pause Rules'!$B$4&"-unit floor) — ads paused to protect the remaining units."),IF($N21,"30D ACOS "&'Input Data'!$E$21&"% is at or above the "&'Pause Rules'!$B$5&"% ceiling; 7D ACOS "&'Input Data'!$F$21&"% is not improving — paused.",IF($O21,'Input Data'!$I$21&" clicks over 14 days with 0 orders; spend "&TEXT('Input Data'!$J$21,"£0.00")&" is at or above the "&TEXT('Pause Rules'!$B$8,"£0.00")&" floor — paused.","No rule matched — the listing keeps running.")))) -> Campaign is already OFF — pause rules are not evaluated. | H21: =IF($L21,"ALREADY OFF",IF($P21,"PAUSED","RUNNING")) -> ALREADY OFF | I21: Pending | L21: =OR('Input Data'!$M$21="OFF",'Input Data'!$N$21="OFF") -> TRUE | M21: =AND('Pause Rules'!$B$11,'Input Data'!$D$21<'Pause Rules'!$B$4) -> FALSE | N21: =AND('Pause Rules'!$B$12,'Input Data'!$G$21>0,'Input Data'!$E$21>='Pause Rules'!$B$5,NOT('Input Data'!$F$21<'Pause Rules'!$B$6)) -> TRUE | O21: =AND('Pause Rules'!$B$13,'Input Data'!$H$21=0,'Input Data'!$I$21>='Pause Rules'!$B$7,NOT('Input Data'!$J$21<'Pause Rules'!$B$8)) -> FALSE | P21: =AND(NOT($L21),OR($M21,$N21,$O21)) -> FALSE
A22: JD | Flush light | Smart | B22: 149867100012 | C22: ='Input Data'!$D$22&" units · "&IF('Input Data'!$D$22<=0,"Out of stock",IF('Input Data'!$D$22<'Pause Rules'!$B$4,"Low stock","In stock")) -> 0 units · Out of stock | D22: ="Campaign "&'Input Data'!$M$22&" / Listing "&'Input Data'!$N$22 -> Campaign OFF / Listing OFF | E22: =IF($L22,"—",IF($M22,"Stock",IF($N22,"Rule 1",IF($O22,"Rule 2","—")))) -> — | F22: =IF(NOT($P22),"—",IF(AND($E22="Stock",'Input Data'!$D$22<=0),"High",IF('Input Data'!$K$22>='Pause Rules'!$B$9,"High",IF('Input Data'!$K$22>='Pause Rules'!$B$10,"Medium","Low")))) -> — | G22: =IF($L22,IF('Input Data'!$M$22="OFF","Campaign","Listing")&" is already OFF — pause rules are not evaluated.",IF($M22,IF('Input Data'!$D$22<=0,"Out of stock (0 units) — ads paused so spend does not run on an unbuyable item.","Low stock ("&'Input Data'!$D$22&" units, below the "&'Pause Rules'!$B$4&"-unit floor) — ads paused to protect the remaining units."),IF($N22,"30D ACOS "&'Input Data'!$E$22&"% is at or above the "&'Pause Rules'!$B$5&"% ceiling; 7D ACOS "&'Input Data'!$F$22&"% is not improving — paused.",IF($O22,'Input Data'!$I$22&" clicks over 14 days with 0 orders; spend "&TEXT('Input Data'!$J$22,"£0.00")&" is at or above the "&TEXT('Pause Rules'!$B$8,"£0.00")&" floor — paused.","No rule matched — the listing keeps running.")))) -> Campaign is already OFF — pause rules are not evaluated. | H22: =IF($L22,"ALREADY OFF",IF($P22,"PAUSED","RUNNING")) -> ALREADY OFF | I22: Pending | L22: =OR('Input Data'!$M$22="OFF",'Input Data'!$N$22="OFF") -> TRUE | M22: =AND('Pause Rules'!$B$11,'Input Data'!$D$22<'Pause Rules'!$B$4) -> TRUE | N22: =AND('Pause Rules'!$B$12,'Input Data'!$G$22>0,'Input Data'!$E$22>='Pause Rules'!$B$5,NOT('Input Data'!$F$22<'Pause Rules'!$B$6)) -> TRUE | O22: =AND('Pause Rules'!$B$13,'Input Data'!$H$22=0,'Input Data'!$I$22>='Pause Rules'!$B$7,NOT('Input Data'!$J$22<'Pause Rules'!$B$8)) -> FALSE | P22: =AND(NOT($L22),OR($M22,$N22,$O22)) -> FALSE
A23: JD | MH | Wire Cage | Paulroshan | Manual | B23: 159695736012 | C23: ='Input Data'!$D$23&" units · "&IF('Input Data'!$D$23<=0,"Out of stock",IF('Input Data'!$D$23<'Pause Rules'!$B$4,"Low stock","In stock")) -> 18 units · In stock | D23: ="Campaign "&'Input Data'!$M$23&" / Listing "&'Input Data'!$N$23 -> Campaign OFF / Listing OFF | E23: =IF($L23,"—",IF($M23,"Stock",IF($N23,"Rule 1",IF($O23,"Rule 2","—")))) -> — | F23: =IF(NOT($P23),"—",IF(AND($E23="Stock",'Input Data'!$D$23<=0),"High",IF('Input Data'!$K$23>='Pause Rules'!$B$9,"High",IF('Input Data'!$K$23>='Pause Rules'!$B$10,"Medium","Low")))) -> — | G23: =IF($L23,IF('Input Data'!$M$23="OFF","Campaign","Listing")&" is already OFF — pause rules are not evaluated.",IF($M23,IF('Input Data'!$D$23<=0,"Out of stock (0 units) — ads paused so spend does not run on an unbuyable item.","Low stock ("&'Input Data'!$D$23&" units, below the "&'Pause Rules'!$B$4&"-unit floor) — ads paused to protect the remaining units."),IF($N23,"30D ACOS "&'Input Data'!$E$23&"% is at or above the "&'Pause Rules'!$B$5&"% ceiling; 7D ACOS "&'Input Data'!$F$23&"% is not improving — paused.",IF($O23,'Input Data'!$I$23&" clicks over 14 days with 0 orders; spend "&TEXT('Input Data'!$J$23,"£0.00")&" is at or above the "&TEXT('Pause Rules'!$B$8,"£0.00")&" floor — paused.","No rule matched — the listing keeps running.")))) -> Campaign is already OFF — pause rules are not evaluated. | H23: =IF($L23,"ALREADY OFF",IF($P23,"PAUSED","RUNNING")) -> ALREADY OFF | I23: Pending | L23: =OR('Input Data'!$M$23="OFF",'Input Data'!$N$23="OFF") -> TRUE | M23: =AND('Pause Rules'!$B$11,'Input Data'!$D$23<'Pause Rules'!$B$4) -> FALSE | N23: =AND('Pause Rules'!$B$12,'Input Data'!$G$23>0,'Input Data'!$E$23>='Pause Rules'!$B$5,NOT('Input Data'!$F$23<'Pause Rules'!$B$6)) -> TRUE | O23: =AND('Pause Rules'!$B$13,'Input Data'!$H$23=0,'Input Data'!$I$23>='Pause Rules'!$B$7,NOT('Input Data'!$J$23<'Pause Rules'!$B$8)) -> FALSE | P23: =AND(NOT($L23),OR($M23,$N23,$O23)) -> FALSE
A24: JD | MH | Ceiling rose & Tapes | Prasath | Manual | B24: 161303270012 | C24: ='Input Data'!$D$24&" units · "&IF('Input Data'!$D$24<=0,"Out of stock",IF('Input Data'!$D$24<'Pause Rules'!$B$4,"Low stock","In stock")) -> 71 units · In stock | D24: ="Campaign "&'Input Data'!$M$24&" / Listing "&'Input Data'!$N$24 -> Campaign OFF / Listing OFF | E24: =IF($L24,"—",IF($M24,"Stock",IF($N24,"Rule 1",IF($O24,"Rule 2","—")))) -> — | F24: =IF(NOT($P24),"—",IF(AND($E24="Stock",'Input Data'!$D$24<=0),"High",IF('Input Data'!$K$24>='Pause Rules'!$B$9,"High",IF('Input Data'!$K$24>='Pause Rules'!$B$10,"Medium","Low")))) -> — | G24: =IF($L24,IF('Input Data'!$M$24="OFF","Campaign","Listing")&" is already OFF — pause rules are not evaluated.",IF($M24,IF('Input Data'!$D$24<=0,"Out of stock (0 units) — ads paused so spend does not run on an unbuyable item.","Low stock ("&'Input Data'!$D$24&" units, below the "&'Pause Rules'!$B$4&"-unit floor) — ads paused to protect the remaining units."),IF($N24,"30D ACOS "&'Input Data'!$E$24&"% is at or above the "&'Pause Rules'!$B$5&"% ceiling; 7D ACOS "&'Input Data'!$F$24&"% is not improving — paused.",IF($O24,'Input Data'!$I$24&" clicks over 14 days with 0 orders; spend "&TEXT('Input Data'!$J$24,"£0.00")&" is at or above the "&TEXT('Pause Rules'!$B$8,"£0.00")&" floor — paused.","No rule matched — the listing keeps running.")))) -> Campaign is already OFF — pause rules are not evaluated. | H24: =IF($L24,"ALREADY OFF",IF($P24,"PAUSED","RUNNING")) -> ALREADY OFF | I24: Pending | L24: =OR('Input Data'!$M$24="OFF",'Input Data'!$N$24="OFF") -> TRUE | M24: =AND('Pause Rules'!$B$11,'Input Data'!$D$24<'Pause Rules'!$B$4) -> FALSE | N24: =AND('Pause Rules'!$B$12,'Input Data'!$G$24>0,'Input Data'!$E$24>='Pause Rules'!$B$5,NOT('Input Data'!$F$24<'Pause Rules'!$B$6)) -> FALSE | O24: =AND('Pause Rules'!$B$13,'Input Data'!$H$24=0,'Input Data'!$I$24>='Pause Rules'!$B$7,NOT('Input Data'!$J$24<'Pause Rules'!$B$8)) -> FALSE | P24: =AND(NOT($L24),OR($M24,$N24,$O24)) -> FALSE
A25: JD | MH | Lighting Accessories & Hardware | Tharsika.T | Manual | B25: 159997785012 | C25: ='Input Data'!$D$25&" units · "&IF('Input Data'!$D$25<=0,"Out of stock",IF('Input Data'!$D$25<'Pause Rules'!$B$4,"Low stock","In stock")) -> 0 units · Out of stock | D25: ="Campaign "&'Input Data'!$M$25&" / Listing "&'Input Data'!$N$25 -> Campaign OFF / Listing OFF | E25: =IF($L25,"—",IF($M25,"Stock",IF($N25,"Rule 1",IF($O25,"Rule 2","—")))) -> — | F25: =IF(NOT($P25),"—",IF(AND($E25="Stock",'Input Data'!$D$25<=0),"High",IF('Input Data'!$K$25>='Pause Rules'!$B$9,"High",IF('Input Data'!$K$25>='Pause Rules'!$B$10,"Medium","Low")))) -> — | G25: =IF($L25,IF('Input Data'!$M$25="OFF","Campaign","Listing")&" is already OFF — pause rules are not evaluated.",IF($M25,IF('Input Data'!$D$25<=0,"Out of stock (0 units) — ads paused so spend does not run on an unbuyable item.","Low stock ("&'Input Data'!$D$25&" units, below the "&'Pause Rules'!$B$4&"-unit floor) — ads paused to protect the remaining units."),IF($N25,"30D ACOS "&'Input Data'!$E$25&"% is at or above the "&'Pause Rules'!$B$5&"% ceiling; 7D ACOS "&'Input Data'!$F$25&"% is not improving — paused.",IF($O25,'Input Data'!$I$25&" clicks over 14 days with 0 orders; spend "&TEXT('Input Data'!$J$25,"£0.00")&" is at or above the "&TEXT('Pause Rules'!$B$8,"£0.00")&" floor — paused.","No rule matched — the listing keeps running.")))) -> Campaign is already OFF — pause rules are not evaluated. | H25: =IF($L25,"ALREADY OFF",IF($P25,"PAUSED","RUNNING")) -> ALREADY OFF | I25: Pending | L25: =OR('Input Data'!$M$25="OFF",'Input Data'!$N$25="OFF") -> TRUE | M25: =AND('Pause Rules'!$B$11,'Input Data'!$D$25<'Pause Rules'!$B$4) -> TRUE | N25: =AND('Pause Rules'!$B$12,'Input Data'!$G$25>0,'Input Data'!$E$25>='Pause Rules'!$B$5,NOT('Input Data'!$F$25<'Pause Rules'!$B$6)) -> TRUE | O25: =AND('Pause Rules'!$B$13,'Input Data'!$H$25=0,'Input Data'!$I$25>='Pause Rules'!$B$7,NOT('Input Data'!$J$25<'Pause Rules'!$B$8)) -> FALSE | P25: =AND(NOT($L25),OR($M25,$N25,$O25)) -> FALSE
A26: JD | PH | PLA | Power Supply | Transformer | Manual | B26: 15603840012 | C26: ='Input Data'!$D$26&" units · "&IF('Input Data'!$D$26<=0,"Out of stock",IF('Input Data'!$D$26<'Pause Rules'!$B$4,"Low stock","In stock")) -> 240 units · In stock | D26: ="Campaign "&'Input Data'!$M$26&" / Listing "&'Input Data'!$N$26 -> Campaign ON / Listing ON | E26: =IF($L26,"—",IF($M26,"Stock",IF($N26,"Rule 1",IF($O26,"Rule 2","—")))) -> — | F26: =IF(NOT($P26),"—",IF(AND($E26="Stock",'Input Data'!$D$26<=0),"High",IF('Input Data'!$K$26>='Pause Rules'!$B$9,"High",IF('Input Data'!$K$26>='Pause Rules'!$B$10,"Medium","Low")))) -> — | G26: =IF($L26,IF('Input Data'!$M$26="OFF","Campaign","Listing")&" is already OFF — pause rules are not evaluated.",IF($M26,IF('Input Data'!$D$26<=0,"Out of stock (0 units) — ads paused so spend does not run on an unbuyable item.","Low stock ("&'Input Data'!$D$26&" units, below the "&'Pause Rules'!$B$4&"-unit floor) — ads paused to protect the remaining units."),IF($N26,"30D ACOS "&'Input Data'!$E$26&"% is at or above the "&'Pause Rules'!$B$5&"% ceiling; 7D ACOS "&'Input Data'!$F$26&"% is not improving — paused.",IF($O26,'Input Data'!$I$26&" clicks over 14 days with 0 orders; spend "&TEXT('Input Data'!$J$26,"£0.00")&" is at or above the "&TEXT('Pause Rules'!$B$8,"£0.00")&" floor — paused.","No rule matched — the listing keeps running.")))) -> No rule matched — the listing keeps running. | H26: =IF($L26,"ALREADY OFF",IF($P26,"PAUSED","RUNNING")) -> RUNNING | I26: Pending | L26: =OR('Input Data'!$M$26="OFF",'Input Data'!$N$26="OFF") -> FALSE | M26: =AND('Pause Rules'!$B$11,'Input Data'!$D$26<'Pause Rules'!$B$4) -> FALSE | N26: =AND('Pause Rules'!$B$12,'Input Data'!$G$26>0,'Input Data'!$E$26>='Pause Rules'!$B$5,NOT('Input Data'!$F$26<'Pause Rules'!$B$6)) -> FALSE | O26: =AND('Pause Rules'!$B$13,'Input Data'!$H$26=0,'Input Data'!$I$26>='Pause Rules'!$B$7,NOT('Input Data'!$J$26<'Pause Rules'!$B$8)) -> FALSE | P26: =AND(NOT($L26),OR($M26,$N26,$O26)) -> FALSE
A27: JD | PH | BULB | TUWA | MANUAL | B27: 155338191012 | C27: ='Input Data'!$D$27&" units · "&IF('Input Data'!$D$27<=0,"Out of stock",IF('Input Data'!$D$27<'Pause Rules'!$B$4,"Low stock","In stock")) -> 512 units · In stock | D27: ="Campaign "&'Input Data'!$M$27&" / Listing "&'Input Data'!$N$27 -> Campaign ON / Listing ON | E27: =IF($L27,"—",IF($M27,"Stock",IF($N27,"Rule 1",IF($O27,"Rule 2","—")))) -> — | F27: =IF(NOT($P27),"—",IF(AND($E27="Stock",'Input Data'!$D$27<=0),"High",IF('Input Data'!$K$27>='Pause Rules'!$B$9,"High",IF('Input Data'!$K$27>='Pause Rules'!$B$10,"Medium","Low")))) -> — | G27: =IF($L27,IF('Input Data'!$M$27="OFF","Campaign","Listing")&" is already OFF — pause rules are not evaluated.",IF($M27,IF('Input Data'!$D$27<=0,"Out of stock (0 units) — ads paused so spend does not run on an unbuyable item.","Low stock ("&'Input Data'!$D$27&" units, below the "&'Pause Rules'!$B$4&"-unit floor) — ads paused to protect the remaining units."),IF($N27,"30D ACOS "&'Input Data'!$E$27&"% is at or above the "&'Pause Rules'!$B$5&"% ceiling; 7D ACOS "&'Input Data'!$F$27&"% is not improving — paused.",IF($O27,'Input Data'!$I$27&" clicks over 14 days with 0 orders; spend "&TEXT('Input Data'!$J$27,"£0.00")&" is at or above the "&TEXT('Pause Rules'!$B$8,"£0.00")&" floor — paused.","No rule matched — the listing keeps running.")))) -> No rule matched — the listing keeps running. | H27: =IF($L27,"ALREADY OFF",IF($P27,"PAUSED","RUNNING")) -> RUNNING | I27: Pending | L27: =OR('Input Data'!$M$27="OFF",'Input Data'!$N$27="OFF") -> FALSE | M27: =AND('Pause Rules'!$B$11,'Input Data'!$D$27<'Pause Rules'!$B$4) -> FALSE | N27: =AND('Pause Rules'!$B$12,'Input Data'!$G$27>0,'Input Data'!$E$27>='Pause Rules'!$B$5,NOT('Input Data'!$F$27<'Pause Rules'!$B$6)) -> FALSE | O27: =AND('Pause Rules'!$B$13,'Input Data'!$H$27=0,'Input Data'!$I$27>='Pause Rules'!$B$7,NOT('Input Data'!$J$27<'Pause Rules'!$B$8)) -> FALSE | P27: =AND(NOT($L27),OR($M27,$N27,$O27)) -> FALSE
A28: JD | PH | All type | Transformer | Manual | B28: 129690774012 | C28: ='Input Data'!$D$28&" units · "&IF('Input Data'!$D$28<=0,"Out of stock",IF('Input Data'!$D$28<'Pause Rules'!$B$4,"Low stock","In stock")) -> 190 units · In stock | D28: ="Campaign "&'Input Data'!$M$28&" / Listing "&'Input Data'!$N$28 -> Campaign ON / Listing ON | E28: =IF($L28,"—",IF($M28,"Stock",IF($N28,"Rule 1",IF($O28,"Rule 2","—")))) -> — | F28: =IF(NOT($P28),"—",IF(AND($E28="Stock",'Input Data'!$D$28<=0),"High",IF('Input Data'!$K$28>='Pause Rules'!$B$9,"High",IF('Input Data'!$K$28>='Pause Rules'!$B$10,"Medium","Low")))) -> — | G28: =IF($L28,IF('Input Data'!$M$28="OFF","Campaign","Listing")&" is already OFF — pause rules are not evaluated.",IF($M28,IF('Input Data'!$D$28<=0,"Out of stock (0 units) — ads paused so spend does not run on an unbuyable item.","Low stock ("&'Input Data'!$D$28&" units, below the "&'Pause Rules'!$B$4&"-unit floor) — ads paused to protect the remaining units."),IF($N28,"30D ACOS "&'Input Data'!$E$28&"% is at or above the "&'Pause Rules'!$B$5&"% ceiling; 7D ACOS "&'Input Data'!$F$28&"% is not improving — paused.",IF($O28,'Input Data'!$I$28&" clicks over 14 days with 0 orders; spend "&TEXT('Input Data'!$J$28,"£0.00")&" is at or above the "&TEXT('Pause Rules'!$B$8,"£0.00")&" floor — paused.","No rule matched — the listing keeps running.")))) -> No rule matched — the listing keeps running. | H28: =IF($L28,"ALREADY OFF",IF($P28,"PAUSED","RUNNING")) -> RUNNING | I28: Pending | L28: =OR('Input Data'!$M$28="OFF",'Input Data'!$N$28="OFF") -> FALSE | M28: =AND('Pause Rules'!$B$11,'Input Data'!$D$28<'Pause Rules'!$B$4) -> FALSE | N28: =AND('Pause Rules'!$B$12,'Input Data'!$G$28>0,'Input Data'!$E$28>='Pause Rules'!$B$5,NOT('Input Data'!$F$28<'Pause Rules'!$B$6)) -> FALSE | O28: =AND('Pause Rules'!$B$13,'Input Data'!$H$28=0,'Input Data'!$I$28>='Pause Rules'!$B$7,NOT('Input Data'!$J$28<'Pause Rules'!$B$8)) -> FALSE | P28: =AND(NOT($L28),OR($M28,$N28,$O28)) -> FALSE
A29: JD | PH | PSU 4 types | Transformer | Manual | B29: 34199100012 | C29: ='Input Data'!$D$29&" units · "&IF('Input Data'!$D$29<=0,"Out of stock",IF('Input Data'!$D$29<'Pause Rules'!$B$4,"Low stock","In stock")) -> 128 units · In stock | D29: ="Campaign "&'Input Data'!$M$29&" / Listing "&'Input Data'!$N$29 -> Campaign ON / Listing ON | E29: =IF($L29,"—",IF($M29,"Stock",IF($N29,"Rule 1",IF($O29,"Rule 2","—")))) -> — | F29: =IF(NOT($P29),"—",IF(AND($E29="Stock",'Input Data'!$D$29<=0),"High",IF('Input Data'!$K$29>='Pause Rules'!$B$9,"High",IF('Input Data'!$K$29>='Pause Rules'!$B$10,"Medium","Low")))) -> — | G29: =IF($L29,IF('Input Data'!$M$29="OFF","Campaign","Listing")&" is already OFF — pause rules are not evaluated.",IF($M29,IF('Input Data'!$D$29<=0,"Out of stock (0 units) — ads paused so spend does not run on an unbuyable item.","Low stock ("&'Input Data'!$D$29&" units, below the "&'Pause Rules'!$B$4&"-unit floor) — ads paused to protect the remaining units."),IF($N29,"30D ACOS "&'Input Data'!$E$29&"% is at or above the "&'Pause Rules'!$B$5&"% ceiling; 7D ACOS "&'Input Data'!$F$29&"% is not improving — paused.",IF($O29,'Input Data'!$I$29&" clicks over 14 days with 0 orders; spend "&TEXT('Input Data'!$J$29,"£0.00")&" is at or above the "&TEXT('Pause Rules'!$B$8,"£0.00")&" floor — paused.","No rule matched — the listing keeps running.")))) -> No rule matched — the listing keeps running. | H29: =IF($L29,"ALREADY OFF",IF($P29,"PAUSED","RUNNING")) -> RUNNING | I29: Pending | L29: =OR('Input Data'!$M$29="OFF",'Input Data'!$N$29="OFF") -> FALSE | M29: =AND('Pause Rules'!$B$11,'Input Data'!$D$29<'Pause Rules'!$B$4) -> FALSE | N29: =AND('Pause Rules'!$B$12,'Input Data'!$G$29>0,'Input Data'!$E$29>='Pause Rules'!$B$5,NOT('Input Data'!$F$29<'Pause Rules'!$B$6)) -> FALSE | O29: =AND('Pause Rules'!$B$13,'Input Data'!$H$29=0,'Input Data'!$I$29>='Pause Rules'!$B$7,NOT('Input Data'!$J$29<'Pause Rules'!$B$8)) -> FALSE | P29: =AND(NOT($L29),OR($M29,$N29,$O29)) -> FALSE
A30: JD | PH | power supply (fast moving) | Transformer | smart | B30: 28863466012 | C30: ='Input Data'!$D$30&" units · "&IF('Input Data'!$D$30<=0,"Out of stock",IF('Input Data'!$D$30<'Pause Rules'!$B$4,"Low stock","In stock")) -> 176 units · In stock | D30: ="Campaign "&'Input Data'!$M$30&" / Listing "&'Input Data'!$N$30 -> Campaign ON / Listing ON | E30: =IF($L30,"—",IF($M30,"Stock",IF($N30,"Rule 1",IF($O30,"Rule 2","—")))) -> — | F30: =IF(NOT($P30),"—",IF(AND($E30="Stock",'Input Data'!$D$30<=0),"High",IF('Input Data'!$K$30>='Pause Rules'!$B$9,"High",IF('Input Data'!$K$30>='Pause Rules'!$B$10,"Medium","Low")))) -> — | G30: =IF($L30,IF('Input Data'!$M$30="OFF","Campaign","Listing")&" is already OFF — pause rules are not evaluated.",IF($M30,IF('Input Data'!$D$30<=0,"Out of stock (0 units) — ads paused so spend does not run on an unbuyable item.","Low stock ("&'Input Data'!$D$30&" units, below the "&'Pause Rules'!$B$4&"-unit floor) — ads paused to protect the remaining units."),IF($N30,"30D ACOS "&'Input Data'!$E$30&"% is at or above the "&'Pause Rules'!$B$5&"% ceiling; 7D ACOS "&'Input Data'!$F$30&"% is not improving — paused.",IF($O30,'Input Data'!$I$30&" clicks over 14 days with 0 orders; spend "&TEXT('Input Data'!$J$30,"£0.00")&" is at or above the "&TEXT('Pause Rules'!$B$8,"£0.00")&" floor — paused.","No rule matched — the listing keeps running.")))) -> No rule matched — the listing keeps running. | H30: =IF($L30,"ALREADY OFF",IF($P30,"PAUSED","RUNNING")) -> RUNNING | I30: Pending | L30: =OR('Input Data'!$M$30="OFF",'Input Data'!$N$30="OFF") -> FALSE | M30: =AND('Pause Rules'!$B$11,'Input Data'!$D$30<'Pause Rules'!$B$4) -> FALSE | N30: =AND('Pause Rules'!$B$12,'Input Data'!$G$30>0,'Input Data'!$E$30>='Pause Rules'!$B$5,NOT('Input Data'!$F$30<'Pause Rules'!$B$6)) -> FALSE | O30: =AND('Pause Rules'!$B$13,'Input Data'!$H$30=0,'Input Data'!$I$30>='Pause Rules'!$B$7,NOT('Input Data'!$J$30<'Pause Rules'!$B$8)) -> FALSE | P30: =AND(NOT($L30),OR($M30,$N30,$O30)) -> FALSE
A31: JD | PLA | Pendent Lights | Smart | B31: 15405839012 | C31: ='Input Data'!$D$31&" units · "&IF('Input Data'!$D$31<=0,"Out of stock",IF('Input Data'!$D$31<'Pause Rules'!$B$4,"Low stock","In stock")) -> 38 units · In stock | D31: ="Campaign "&'Input Data'!$M$31&" / Listing "&'Input Data'!$N$31 -> Campaign ON / Listing ON | E31: =IF($L31,"—",IF($M31,"Stock",IF($N31,"Rule 1",IF($O31,"Rule 2","—")))) -> — | F31: =IF(NOT($P31),"—",IF(AND($E31="Stock",'Input Data'!$D$31<=0),"High",IF('Input Data'!$K$31>='Pause Rules'!$B$9,"High",IF('Input Data'!$K$31>='Pause Rules'!$B$10,"Medium","Low")))) -> — | G31: =IF($L31,IF('Input Data'!$M$31="OFF","Campaign","Listing")&" is already OFF — pause rules are not evaluated.",IF($M31,IF('Input Data'!$D$31<=0,"Out of stock (0 units) — ads paused so spend does not run on an unbuyable item.","Low stock ("&'Input Data'!$D$31&" units, below the "&'Pause Rules'!$B$4&"-unit floor) — ads paused to protect the remaining units."),IF($N31,"30D ACOS "&'Input Data'!$E$31&"% is at or above the "&'Pause Rules'!$B$5&"% ceiling; 7D ACOS "&'Input Data'!$F$31&"% is not improving — paused.",IF($O31,'Input Data'!$I$31&" clicks over 14 days with 0 orders; spend "&TEXT('Input Data'!$J$31,"£0.00")&" is at or above the "&TEXT('Pause Rules'!$B$8,"£0.00")&" floor — paused.","No rule matched — the listing keeps running.")))) -> No rule matched — the listing keeps running. | H31: =IF($L31,"ALREADY OFF",IF($P31,"PAUSED","RUNNING")) -> RUNNING | I31: Pending | L31: =OR('Input Data'!$M$31="OFF",'Input Data'!$N$31="OFF") -> FALSE | M31: =AND('Pause Rules'!$B$11,'Input Data'!$D$31<'Pause Rules'!$B$4) -> FALSE | N31: =AND('Pause Rules'!$B$12,'Input Data'!$G$31>0,'Input Data'!$E$31>='Pause Rules'!$B$5,NOT('Input Data'!$F$31<'Pause Rules'!$B$6)) -> FALSE | O31: =AND('Pause Rules'!$B$13,'Input Data'!$H$31=0,'Input Data'!$I$31>='Pause Rules'!$B$7,NOT('Input Data'!$J$31<'Pause Rules'!$B$8)) -> FALSE | P31: =AND(NOT($L31),OR($M31,$N31,$O31)) -> FALSE
